Traceback (most recent call last):
  File "/home/user/sensors/src/main.py", line 151, in <module>
    display_activity()
  File "/home/user/sensors/src/main.py", line 87, in display_activity
    display.display(image)
  File "/home/user/sensors/venv/lib/python3.11/site-packages/luma/oled/device/__init__.py", line 311, in display
    self.data(list(buf))
  File "/home/user/sensors/venv/lib/python3.11/site-packages/luma/core/device.py", line 55, in data
    self._serial_interface.data(data)
  File "/home/user/sensors/venv/lib/python3.11/site-packages/luma/core/interface/serial.py", line 128, in data
    write(list(data[i:i + block_size]))
  File "/home/user/sensors/venv/lib/python3.11/site-packages/luma/core/interface/serial.py", line 137, in _write_large_block
    self._bus.i2c_rdwr(self._i2c_msg_write(self._addr, [self._data_mode] + data))
  File "/home/user/sensors/venv/lib/python3.11/site-packages/smbus2/smbus2.py", line 660, in i2c_rdwr
    ioctl(self.fd, I2C_RDWR, ioctl_data)
OSError: [Errno 5] Input/output error
python3: can't open file '/home/user/sensors/main.py': [Errno 2] No such file or directory
Traceback (most recent call last):
  File "/home/user/sensors/venv/lib/python3.11/site-packages/luma/core/interface/serial.py", line 93, in command
    self._bus.write_i2c_block_data(self._addr, self._cmd_mode,
  File "/home/user/sensors/venv/lib/python3.11/site-packages/smbus2/smbus2.py", line 645, in write_i2c_block_data
    ioctl(self.fd, I2C_SMBUS, msg)
OSError: [Errno 5] Input/output error

During handling of the above exception, another exception occurred:

Traceback (most recent call last):
  File "/home/user/sensors/src/main.py", line 19, in <module>
    display = ssd1306(ser)
              ^^^^^^^^^^^^
  File "/home/user/sensors/venv/lib/python3.11/site-packages/luma/oled/device/__init__.py", line 262, in __init__
    self.command(
  File "/home/user/sensors/venv/lib/python3.11/site-packages/luma/core/device.py", line 48, in command
    self._serial_interface.command(*cmd)
  File "/home/user/sensors/venv/lib/python3.11/site-packages/luma/core/interface/serial.py", line 98, in command
    raise luma.core.error.DeviceNotFoundError(
luma.core.error.DeviceNotFoundError: I2C device not found on address: 0x3C
Traceback (most recent call last):
  File "/home/user/sensors/venv/lib/python3.11/site-packages/serial/serialposix.py", line 322, in open
    self.fd = os.open(self.portstr, os.O_RDWR | os.O_NOCTTY | os.O_NONBLOCK)
              ^^^^^^^^^^^^^^^^^^^^^^^^^^^^^^^^^^^^^^^^^^^^^^^^^^^^^^^^^^^^^^
PermissionError: [Errno 13] Permission denied: '/dev/serial0'

During handling of the above exception, another exception occurred:

Traceback (most recent call last):
  File "/home/user/sensors/src/main.py", line 29, in <module>
    uart = serial.Serial("/dev/serial0", baudrate=9600, timeout=30)
           ^^^^^^^^^^^^^^^^^^^^^^^^^^^^^^^^^^^^^^^^^^^^^^^^^^^^^^^^
  File "/home/user/sensors/venv/lib/python3.11/site-packages/serial/serialutil.py", line 244, in __init__
    self.open()
  File "/home/user/sensors/venv/lib/python3.11/site-packages/serial/serialposix.py", line 325, in open
    raise SerialException(msg.errno, "could not open port {}: {}".format(self._port, msg))
serial.serialutil.SerialException: [Errno 13] could not open port /dev/serial0: [Errno 13] Permission denied: '/dev/serial0'
Traceback (most recent call last):
  File "/home/user/sensors/venv/lib/python3.11/site-packages/luma/core/interface/serial.py", line 93, in command
    self._bus.write_i2c_block_data(self._addr, self._cmd_mode,
  File "/home/user/sensors/venv/lib/python3.11/site-packages/smbus2/smbus2.py", line 645, in write_i2c_block_data
    ioctl(self.fd, I2C_SMBUS, msg)
OSError: [Errno 5] Input/output error

During handling of the above exception, another exception occurred:

Traceback (most recent call last):
  File "/home/user/sensors/src/main.py", line 151, in <module>
    display_activity()
  File "/home/user/sensors/src/main.py", line 87, in display_activity
    display.display(image)
  File "/home/user/sensors/venv/lib/python3.11/site-packages/luma/oled/device/__init__.py", line 295, in display
    self.command(
  File "/home/user/sensors/venv/lib/python3.11/site-packages/luma/core/device.py", line 48, in command
    self._serial_interface.command(*cmd)
  File "/home/user/sensors/venv/lib/python3.11/site-packages/luma/core/interface/serial.py", line 98, in command
    raise luma.core.error.DeviceNotFoundError(
luma.core.error.DeviceNotFoundError: I2C device not found on address: 0x3C
Traceback (most recent call last):
  File "/home/user/sensors/src/main.py", line 4, in <module>
    import adafruit_gps
  File "/home/user/sensors/venv/lib/python3.11/site-packages/adafruit_gps.py", line 38, in <module>
    from circuitpython_typing import ReadableBuffer
  File "/home/user/sensors/venv/lib/python3.11/site-packages/circuitpython_typing/__init__.py", line 21, in <module>
    from typing_extensions import Protocol, TypeAlias
  File "/home/user/sensors/venv/lib/python3.11/site-packages/typing_extensions.py", line 8, in <module>
    import inspect
  File "/usr/lib/python3.11/inspect.py", line 143, in <module>
    import linecache
  File "/usr/lib/python3.11/linecache.py", line 11, in <module>
    import tokenize
  File "<frozen importlib._bootstrap>", line 1178, in _find_and_load
  File "<frozen importlib._bootstrap>", line 1140, in _find_and_load_unlocked
  File "<frozen importlib._bootstrap>", line 1080, in _find_spec
  File "<frozen importlib._bootstrap_external>", line 1504, in find_spec
  File "<frozen importlib._bootstrap_external>", line 1476, in _get_spec
  File "<frozen importlib._bootstrap_external>", line 1645, in find_spec
  File "<frozen importlib._bootstrap_external>", line 161, in _path_isfile
  File "<frozen importlib._bootstrap_external>", line 153, in _path_is_mode_type
  File "<frozen importlib._bootstrap_external>", line 147, in _path_stat
KeyboardInterrupt
